Исключение лежит в макрозадаче, она исполнится только после завершения остального кода. К этому моменту catch уже "закончился".